519f57e4c7291d40c9ea57b224044846c3cdca57: Pulling from gr0v1ty/nano-node
857cc8cb19c0: Already exists
18681f110048: Pulling fs layer
4d316141e169: Pulling fs layer
60feb5b0bb0c: Pulling fs layer
85c13a3e0221: Pulling fs layer
abbdaca27156: Pulling fs layer
4593365ae4cb: Pulling fs layer
7e3766fac96d: Pulling fs layer
4f4fb700ef54: Pulling fs layer
b79e15d6f06e: Pulling fs layer
5b0f71258b58: Pulling fs layer
5b0f71258b58: Waiting
7e3766fac96d: Waiting
4f4fb700ef54: Waiting
85c13a3e0221: Waiting
abbdaca27156: Waiting
4593365ae4cb: Waiting
b79e15d6f06e: Waiting
18681f110048: Verifying Checksum
18681f110048: Download complete
85c13a3e0221: Verifying Checksum
85c13a3e0221: Download complete
abbdaca27156: Verifying Checksum
abbdaca27156: Download complete
60feb5b0bb0c: Verifying Checksum
60feb5b0bb0c: Download complete
4593365ae4cb: Download complete
4f4fb700ef54: Verifying Checksum
4f4fb700ef54: Download complete
7e3766fac96d: Verifying Checksum
7e3766fac96d: Download complete
18681f110048: Pull complete
b79e15d6f06e: Verifying Checksum
b79e15d6f06e: Download complete
5b0f71258b58: Verifying Checksum
5b0f71258b58: Download complete
4d316141e169: Verifying Checksum
4d316141e169: Download complete
4d316141e169: Pull complete
60feb5b0bb0c: Pull complete
85c13a3e0221: Pull complete
abbdaca27156: Pull complete
4593365ae4cb: Pull complete
7e3766fac96d: Pull complete
4f4fb700ef54: Pull complete
b79e15d6f06e: Pull complete
5b0f71258b58: Pull complete
Digest: sha256:b68753f14179ff99dfdaa78f14894cd4dc123af6e7b40eb8762bd24f2320bd36
Status: Downloaded newer image for gr0v1ty/nano-node:519f57e4c7291d40c9ea57b224044846c3cdca57
docker.io/gr0v1ty/nano-node:519f57e4c7291d40c9ea57b224044846c3cdca57
https://api.github.com/repos/gr0vity-dev/nanolab-configs/contents/quick_testing/5n4pr_conf_10k_change.json
Start Fetching '5n4pr_conf_10k_change_config.json' to '/home/runner/work/nano-node-builder/nano-node-builder/testcases/5n4pr_conf_10k_change_config.json'
Done  Fetching '5n4pr_conf_10k_change_config.json' to '/home/runner/work/nano-node-builder/nano-node-builder/testcases/5n4pr_conf_10k_change_config.json'
Start Fetching '5n4pr_bucket_rounds_short.json' to '/home/runner/work/nano-node-builder/nano-node-builder/testcases/downloads/5n4pr_bucket_rounds_short.json'
Done  Fetching '5n4pr_bucket_rounds_short.json' to '/home/runner/work/nano-node-builder/nano-node-builder/testcases/downloads/5n4pr_bucket_rounds_short.json'
Start Fetching '5n4pr_bucket0-1-88-90-100_10kaccs.ldb' to '/home/runner/work/nano-node-builder/nano-node-builder/testcases/downloads/5n4pr_bucket0-1-88-90-100_10kaccs.ldb'
Done  Fetching '5n4pr_bucket0-1-88-90-100_10kaccs.ldb' to '/home/runner/work/nano-node-builder/nano-node-builder/testcases/downloads/5n4pr_bucket0-1-88-90-100_10kaccs.ldb'
Start Fetching '5n4pr_quicktesting_config.toml' to '/home/runner/work/nano-node-builder/nano-node-builder/testcases/downloads/5n4pr_quicktesting_config.toml'
Done  Fetching '5n4pr_quicktesting_config.toml' to '/home/runner/work/nano-node-builder/nano-node-builder/testcases/downloads/5n4pr_quicktesting_config.toml'
Start Fetching 'config-node_5n4pr_spam_buffer.toml' to '/home/runner/work/nano-node-builder/nano-node-builder/testcases/downloads/config-node_5n4pr_spam_buffer.toml'
Done  Fetching 'config-node_5n4pr_spam_buffer.toml' to '/home/runner/work/nano-node-builder/nano-node-builder/testcases/downloads/config-node_5n4pr_spam_buffer.toml'
Error executing command: nanomock create && nanomock reset
Error: INFO: nanomock data has been copied to your current working directory.
INFO: Log level : default
INFO: Log level : default
INFO: Log level : default
INFO: Log level : default
INFO: Log level : default
SUCCESS: Docker Compose file created at /home/runner/work/nano-node-builder/nano-node-builder/nano_nodes/docker-compose.yml
SUCCESS: None
SUCCESS: init_containers completed with None result.
SUCCESS: stop_containers completed with None result.
SUCCESS: reset_nodes_data completed with None result.
The network 'nl_nano-local' already exists.
Error executing command: nanomock create
Error: INFO: nanomock data has been copied to your current working directory.
INFO: Log level : default
INFO: Log level : default
INFO: Log level : default
INFO: Log level : default
INFO: Log level : default
SUCCESS: Docker Compose file created at /home/runner/work/nano-node-builder/nano-node-builder/nano_nodes/docker-compose.yml
SUCCESS: None
SUCCESS: init_containers completed with None result.
Error executing command: nanomock start && nanomock init_wallets
Error: ERROR: Command failed: docker-compose -f /home/runner/work/nano-node-builder/nano-node-builder/nano_nodes/docker-compose.yml -p nanomock up -d
ERROR: Error output: Creating volume "nanomock_nl_default_volume" with default driver
Creating nl_pr4 ... 
Creating nl_pr2 ... 
Creating nl_pr1 ... 
Creating nl_pr3 ... 
Creating nl_genesis ... 
Creating nl_pr3     ... done
Creating nl_pr1     ... done
Creating nl_pr2     ... done
Creating nl_pr4     ... done
Creating nl_pr1_exporter ... 
Creating nl_pr3_exporter ... 
Creating nl_genesis      ... done
Creating nl_pr2_exporter ... 
Creating nl_pr4_exporter ... 
Creating nl_genesis_exporter ... 
Creating nl_pr1_exporter     ... done
Creating nl_pr4_exporter     ... done
Creating nl_pr2_exporter     ... done
Creating nl_pr3_exporter     ... done
Creating nl_genesis_exporter ... error

ERROR: for nl_genesis_exporter  Cannot start service nl_genesis_exporter: OCI runtime start failed: cannot start a container that has stopped: unknown

ERROR: for nl_genesis_exporter  Cannot start service nl_genesis_exporter: OCI runtime start failed: cannot start a container that has stopped: unknown
Encountered errors while bringing up the project.

ERROR: Return code: 1
Traceback (most recent call last):
  File "/opt/hostedtoolcache/Python/3.8.18/x64/lib/python3.8/site-packages/nanomock/internal/utils.py", line 198, in subprocess_run_capture_output
    result = subprocess.run(cmd,
  File "/opt/hostedtoolcache/Python/3.8.18/x64/lib/python3.8/subprocess.py", line 516, in run
    raise CalledProcessError(retcode, process.args,
subprocess.CalledProcessError: Command 'docker-compose -f /home/runner/work/nano-node-builder/nano-node-builder/nano_nodes/docker-compose.yml -p nanomock up -d' returned non-zero exit status 1.

During handling of the above exception, another exception occurred:

Traceback (most recent call last):
  File "/opt/hostedtoolcache/Python/3.8.18/x64/bin/nanomock", line 8, in <module>
    sys.exit(main())
  File "/opt/hostedtoolcache/Python/3.8.18/x64/lib/python3.8/site-packages/nanomock/main.py", line 58, in main
    asyncio.run(main_async(args))
  File "/opt/hostedtoolcache/Python/3.8.18/x64/lib/python3.8/asyncio/runners.py", line 44, in run
    return loop.run_until_complete(main)
  File "/opt/hostedtoolcache/Python/3.8.18/x64/lib/python3.8/asyncio/base_events.py", line 616, in run_until_complete
    return future.result()
  File "/opt/hostedtoolcache/Python/3.8.18/x64/lib/python3.8/site-packages/nanomock/main.py", line 54, in main_async
    await manager.execute_command(args.command, args.nodes, args.payload)
  File "/opt/hostedtoolcache/Python/3.8.18/x64/lib/python3.8/site-packages/nanomock/nanomock_manager.py", line 544, in execute_command
    await command_func(**filtered_command_args)
  File "/opt/hostedtoolcache/Python/3.8.18/x64/lib/python3.8/site-packages/nanomock/internal/utils.py", line 57, in async_wrapper
    result = await func(*args, **kwargs)
  File "/opt/hostedtoolcache/Python/3.8.18/x64/lib/python3.8/site-packages/nanomock/nanomock_manager.py", line 473, in start_containers
    self.docker_interface.compose_start(nodes)
  File "/opt/hostedtoolcache/Python/3.8.18/x64/lib/python3.8/site-packages/nanomock/docker/mixin.py", line 56, in compose_start
    return self._run_command(cmd)
  File "/opt/hostedtoolcache/Python/3.8.18/x64/lib/python3.8/site-packages/nanomock/docker/mixin.py", line 33, in _run_command
    subprocess_run_capture_output(base_command)
  File "/opt/hostedtoolcache/Python/3.8.18/x64/lib/python3.8/site-packages/nanomock/internal/utils.py", line 209, in subprocess_run_capture_output
    raise subprocess.CalledProcessError(
subprocess.CalledProcessError: <exception str() failed>
Connecting to [::ffff:172.17.0.1]:44100
[Errno 111] Connection refused
Connecting to [::ffff:172.17.0.1]:44101
Connecting to [::ffff:172.17.0.1]:44100
[Errno 111] Connection refused
Connecting to [::ffff:172.17.0.1]:44102
[Errno 111] Connection refused
Connecting to [::ffff:172.17.0.1]:44101
[Errno 111] Connection refused
[Errno 111] Connection refused
Connecting to [::ffff:172.17.0.1]:44102
Connecting to [::ffff:172.17.0.1]:44103
[Errno 111] Connection refused
Connecting to [::ffff:172.17.0.1]:44104
[Errno 111] Connection refused
Connecting to [::ffff:172.17.0.1]:44103
[Errno 111] Connection refused
[Errno 111] Connection refused
Connecting to [::ffff:172.17.0.1]:44104
Connecting to [::ffff:172.17.0.1]:44100
[Errno 111] Connection refused
[Errno 111] Connection refused
Connecting to [::ffff:172.17.0.1]:44101
[Errno 111] Connection refused
Connecting to [::ffff:172.17.0.1]:44102
Connecting to [::ffff:172.17.0.1]:44100
[Errno 111] Connection refused
Connecting to [::ffff:172.17.0.1]:44101
[Errno 111] Connection refused
Connecting to [::ffff:172.17.0.1]:44102
[Errno 111] Connection refused
Connecting to [::ffff:172.17.0.1]:44103
[Errno 111] Connection refused
[Errno 111] Connection refused
Connecting to [::ffff:172.17.0.1]:44103
Connecting to [::ffff:172.17.0.1]:44104
[Errno 111] Connection refused
Connecting to [::ffff:172.17.0.1]:44104
[Errno 111] Connection refused
[Errno 111] Connection refused
Connecting to [::ffff:172.17.0.1]:44100
[Errno 111] Connection refused
Connecting to [::ffff:172.17.0.1]:44101
[Errno 111] Connection refused
Connecting to [::ffff:172.17.0.1]:44102
[Errno 111] Connection refused
Exception in thread Thread-1:
Traceback (most recent call last):
  File "/opt/hostedtoolcache/Python/3.8.18/x64/lib/python3.8/asyncio/selector_events.py", line 848, in _read_ready__data_received
    data = self._sock.recv(self.max_size)
ConnectionResetError: [Errno 104] Connection reset by peer

The above exception was the direct cause of the following exception:

Traceback (most recent call last):
  File "/opt/hostedtoolcache/Python/3.8.18/x64/lib/python3.8/threading.py", line 932, in _bootstrap_inner
    self.run()
  File "/opt/hostedtoolcache/Python/3.8.18/x64/lib/python3.8/threading.py", line 870, in run
    self._target(*self._args, **self._kwargs)
  File "/opt/hostedtoolcache/Python/3.8.18/x64/lib/python3.8/site-packages/nanolab/command/command.py", line 49, in execute_another_command
    another_command.execute()
  File "/opt/hostedtoolcache/Python/3.8.18/x64/lib/python3.8/site-packages/nanolab/command/command.py", line 41, in execute
    self.mixin.execute()
  File "/opt/hostedtoolcache/Python/3.8.18/x64/lib/python3.8/site-packages/nanolab/command/mixins/python_command_mixin.py", line 40, in execute
    method(**filtered_variables)
  File "/opt/hostedtoolcache/Python/3.8.18/x64/lib/python3.8/site-packages/nanolab/pycmd.py", line 30, in start_logger
    asyncio.run(nni.start_loggers(logger_params, sink_params))
  File "/opt/hostedtoolcache/Python/3.8.18/x64/lib/python3.8/asyncio/runners.py", line 44, in run
    return loop.run_until_complete(main)
  File "/opt/hostedtoolcache/Python/3.8.18/x64/lib/python3.8/asyncio/base_events.py", line 616, in run_until_complete
    return future.result()
  File "/opt/hostedtoolcache/Python/3.8.18/x64/lib/python3.8/site-packages/nanolab/node_interaction.py", line 17, in start_loggers
    await logger_manager.start_logging()
  File "/opt/hostedtoolcache/Python/3.8.18/x64/lib/python3.8/site-packages/nanolab/loggers/logger_manager.py", line 45, in start_logging
    async for logger, storages in self.create_loggers():
  File "/opt/hostedtoolcache/Python/3.8.18/x64/lib/python3.8/site-packages/nanolab/loggers/logger_manager.py", line 41, in create_loggers
    yield await self.create_logger_and_storages(current_params)
  File "/opt/hostedtoolcache/Python/3.8.18/x64/lib/python3.8/site-packages/nanolab/loggers/logger_manager.py", line 22, in create_logger_and_storages
    logger = await LoggerFactory.create_logger(self.logger_type,
  File "/opt/hostedtoolcache/Python/3.8.18/x64/lib/python3.8/site-packages/nanolab/loggers/factories/logger_factory.py", line 21, in create_logger
    return await builder.build()
  File "/opt/hostedtoolcache/Python/3.8.18/x64/lib/python3.8/site-packages/nanolab/loggers/builders.py", line 44, in build
    await logger.async_init()
  File "/opt/hostedtoolcache/Python/3.8.18/x64/lib/python3.8/site-packages/nanolab/loggers/sources/rpc_logger.py", line 31, in async_init
    self.count_start, self.cemented_start = await self._get_block_count()
  File "/opt/hostedtoolcache/Python/3.8.18/x64/lib/python3.8/site-packages/nanolab/loggers/sources/rpc_logger.py", line 40, in _get_block_count
    block_count = await self.nanorpc.block_count()
  File "/opt/hostedtoolcache/Python/3.8.18/x64/lib/python3.8/site-packages/nanomock/modules/nl_rpc.py", line 37, in block_count
    return await self.nanorpc.block_count(include_cemented=include_cemented)
  File "/opt/hostedtoolcache/Python/3.8.18/x64/lib/python3.8/site-packages/nanorpc/client.py", line 50, in block_count
    return await self.rpc.block_count(include_cemented=include_cemented)
  File "/opt/hostedtoolcache/Python/3.8.18/x64/lib/python3.8/site-packages/nanorpc/client_dynamic.py", line 33, in method
    return await self.process_payloads([payload])
  File "/opt/hostedtoolcache/Python/3.8.18/x64/lib/python3.8/site-packages/nanorpc/client_dynamic.py", line 119, in process_payloads
    return await self._request_with_retry(self._request, payloads)
  File "/opt/hostedtoolcache/Python/3.8.18/x64/lib/python3.8/site-packages/nanorpc/client_dynamic.py", line 101, in _request_with_retry
    return await self._retry_on_exception(coroutine,
  File "/opt/hostedtoolcache/Python/3.8.18/x64/lib/python3.8/site-packages/nanorpc/client_dynamic.py", line 92, in _retry_on_exception
    return await coroutine(*args)
  File "/opt/hostedtoolcache/Python/3.8.18/x64/lib/python3.8/site-packages/nanorpc/client_dynamic.py", line 108, in _request
    async with session.post(self.url, json=payloads[0], headers=self.headers) as response:
  File "/opt/hostedtoolcache/Python/3.8.18/x64/lib/python3.8/site-packages/aiohttp/client.py", line 1353, in __aenter__
    self._resp = await self._coro
  File "/opt/hostedtoolcache/Python/3.8.18/x64/lib/python3.8/site-packages/aiohttp/client.py", line 684, in _request
    await resp.start(conn)
  File "/opt/hostedtoolcache/Python/3.8.18/x64/lib/python3.8/site-packages/aiohttp/client_reqrep.py", line 999, in start
    message, payload = await protocol.read()  # type: ignore[union-attr]
  File "/opt/hostedtoolcache/Python/3.8.18/x64/lib/python3.8/site-packages/aiohttp/streams.py", line 640, in read
    await self._waiter
aiohttp.client_exceptions.ClientOSError: [Errno 104] Connection reset by peer
Connecting to [::ffff:172.17.0.1]:44103
[Errno 111] Connection refused
Connecting to [::ffff:172.17.0.1]:44104
[Errno 111] Connection refused
Connecting to [::ffff:172.17.0.1]:44100
[Errno 111] Connection refused
Connecting to [::ffff:172.17.0.1]:44101
[Errno 111] Connection refused
Connecting to [::ffff:172.17.0.1]:44102
[Errno 111] Connection refused
Connecting to [::ffff:172.17.0.1]:44103
[Errno 111] Connection refused
Connecting to [::ffff:172.17.0.1]:44104
[Errno 111] Connection refused
