904b553fd2ea22a04727d5ed8db5e6869241484f: Pulling from gr0v1ty/nano-node
60d98d907669: Pulling fs layer
875abfc93578: Pulling fs layer
eebdf30ec20a: Pulling fs layer
0c8b8489542a: Pulling fs layer
9428ba29f782: Pulling fs layer
6ee34e87cf56: Pulling fs layer
83778a7d3a8f: Pulling fs layer
499b7417344b: Pulling fs layer
4f4fb700ef54: Pulling fs layer
c266dc08afc8: Pulling fs layer
75f663d09efc: Pulling fs layer
499b7417344b: Waiting
4f4fb700ef54: Waiting
c266dc08afc8: Waiting
0c8b8489542a: Waiting
75f663d09efc: Waiting
9428ba29f782: Waiting
6ee34e87cf56: Waiting
83778a7d3a8f: Waiting
875abfc93578: Verifying Checksum
875abfc93578: Download complete
0c8b8489542a: Verifying Checksum
0c8b8489542a: Download complete
9428ba29f782: Download complete
60d98d907669: Download complete
6ee34e87cf56: Verifying Checksum
6ee34e87cf56: Download complete
83778a7d3a8f: Verifying Checksum
83778a7d3a8f: Download complete
499b7417344b: Verifying Checksum
499b7417344b: Download complete
4f4fb700ef54: Verifying Checksum
4f4fb700ef54: Download complete
c266dc08afc8: Verifying Checksum
c266dc08afc8: Download complete
60d98d907669: Pull complete
75f663d09efc: Verifying Checksum
75f663d09efc: Download complete
875abfc93578: Pull complete
eebdf30ec20a: Verifying Checksum
eebdf30ec20a: Download complete
eebdf30ec20a: Pull complete
0c8b8489542a: Pull complete
9428ba29f782: Pull complete
6ee34e87cf56: Pull complete
83778a7d3a8f: Pull complete
499b7417344b: Pull complete
4f4fb700ef54: Pull complete
c266dc08afc8: Pull complete
75f663d09efc: Pull complete
Digest: sha256:7bd2aecb8a27f1d668fb02d98972c62d2936e7c9bce18bee1c2dab0077891b3d
Status: Downloaded newer image for gr0v1ty/nano-node:904b553fd2ea22a04727d5ed8db5e6869241484f
docker.io/gr0v1ty/nano-node:904b553fd2ea22a04727d5ed8db5e6869241484f
https://api.github.com/repos/gr0vity-dev/nanolab-configs/contents/quick_testing/5n4pr_rocks_10k_change.json
Start Fetching '5n4pr_rocks_10k_change_config.json' to '/home/runner/work/nano-node-builder/nano-node-builder/testcases/5n4pr_rocks_10k_change_config.json'
Done  Fetching '5n4pr_rocks_10k_change_config.json' to '/home/runner/work/nano-node-builder/nano-node-builder/testcases/5n4pr_rocks_10k_change_config.json'
Start Fetching '5n4pr_bucket_rounds_short.json' to '/home/runner/work/nano-node-builder/nano-node-builder/testcases/downloads/5n4pr_bucket_rounds_short.json'
Done  Fetching '5n4pr_bucket_rounds_short.json' to '/home/runner/work/nano-node-builder/nano-node-builder/testcases/downloads/5n4pr_bucket_rounds_short.json'
Start Fetching '5n4pr_buckets_rocksdb.tar.gz' to '/home/runner/work/nano-node-builder/nano-node-builder/testcases/downloads/5n4pr_buckets_rocksdb.tar.gz'
Done  Fetching '5n4pr_buckets_rocksdb.tar.gz' to '/home/runner/work/nano-node-builder/nano-node-builder/testcases/downloads/5n4pr_buckets_rocksdb.tar.gz'
Start Fetching '5n4pr_quicktesting_config.toml' to '/home/runner/work/nano-node-builder/nano-node-builder/testcases/downloads/5n4pr_quicktesting_config.toml'
Done  Fetching '5n4pr_quicktesting_config.toml' to '/home/runner/work/nano-node-builder/nano-node-builder/testcases/downloads/5n4pr_quicktesting_config.toml'
Start Fetching 'config-node_5n4pr_spam_buffer_rocks.toml' to '/home/runner/work/nano-node-builder/nano-node-builder/testcases/downloads/config-node_5n4pr_spam_buffer_rocks.toml'
Done  Fetching 'config-node_5n4pr_spam_buffer_rocks.toml' to '/home/runner/work/nano-node-builder/nano-node-builder/testcases/downloads/config-node_5n4pr_spam_buffer_rocks.toml'
Error executing command: nanomock create && nanomock reset
Error: INFO: nanomock data has been copied to your current working directory.
INFO: Log level : default
INFO: Log level : default
INFO: Log level : default
INFO: Log level : default
INFO: Log level : default
SUCCESS: Docker Compose file created at /home/runner/work/nano-node-builder/nano-node-builder/nano_nodes/docker-compose.yml
SUCCESS: None
SUCCESS: init_containers completed with None result.
SUCCESS: stop_containers completed with None result.
SUCCESS: reset_nodes_data completed with None result.
The network 'nl_nano-local' already exists.
Error executing command: nanomock create
Error: INFO: nanomock data has been copied to your current working directory.
INFO: Log level : default
INFO: Log level : default
INFO: Log level : default
INFO: Log level : default
INFO: Log level : default
SUCCESS: Docker Compose file created at /home/runner/work/nano-node-builder/nano-node-builder/nano_nodes/docker-compose.yml
SUCCESS: None
SUCCESS: init_containers completed with None result.
Error executing command: nanomock start && nanomock init_wallets
Error: ERROR: Command failed: docker-compose -f /home/runner/work/nano-node-builder/nano-node-builder/nano_nodes/docker-compose.yml -p nanomock up -d
ERROR: Error output: Creating volume "nanomock_nl_default_volume" with default driver
Creating nl_genesis ... 
Creating nl_pr2     ... 
Creating nl_pr4     ... 
Creating nl_pr1     ... 
Creating nl_pr3     ... 
Creating nl_pr3     ... done
Creating nl_pr3_exporter ... 
Creating nl_pr4          ... done
Creating nl_pr4_exporter ... 
Creating nl_pr2          ... done
Creating nl_pr2_exporter ... 
Creating nl_pr1          ... done
Creating nl_pr1_exporter ... 
Creating nl_pr3_exporter ... done
Host is already in use by another container
Creating nl_genesis      ... error

ERROR: for nl_genesis  Cannot start service nl_genesis: failed to set up container networking: driver failed programming external connectivity on endpoint nl_genesis (15887e01c8d3c0d4d3783adcf1240fd76121077f589effdeda5c87817a549e58): failed to bind host port for 0.0.0.0:44100:172.18.0.6:17075/tcp: address already in use
Creating nl_pr4_exporter ... done
Creating nl_pr2_exporter ... done
Creating nl_pr1_exporter ... done

ERROR: for nl_genesis  Cannot start service nl_genesis: failed to set up container networking: driver failed programming external connectivity on endpoint nl_genesis (15887e01c8d3c0d4d3783adcf1240fd76121077f589effdeda5c87817a549e58): failed to bind host port for 0.0.0.0:44100:172.18.0.6:17075/tcp: address already in use
Encountered errors while bringing up the project.

ERROR: Return code: 1
Traceback (most recent call last):
  File "/opt/hostedtoolcache/Python/3.8.18/x64/lib/python3.8/site-packages/nanomock/internal/utils.py", line 198, in subprocess_run_capture_output
    result = subprocess.run(cmd,
  File "/opt/hostedtoolcache/Python/3.8.18/x64/lib/python3.8/subprocess.py", line 516, in run
    raise CalledProcessError(retcode, process.args,
subprocess.CalledProcessError: Command 'docker-compose -f /home/runner/work/nano-node-builder/nano-node-builder/nano_nodes/docker-compose.yml -p nanomock up -d' returned non-zero exit status 1.

During handling of the above exception, another exception occurred:

Traceback (most recent call last):
  File "/opt/hostedtoolcache/Python/3.8.18/x64/bin/nanomock", line 8, in <module>
    sys.exit(main())
  File "/opt/hostedtoolcache/Python/3.8.18/x64/lib/python3.8/site-packages/nanomock/main.py", line 58, in main
    asyncio.run(main_async(args))
  File "/opt/hostedtoolcache/Python/3.8.18/x64/lib/python3.8/asyncio/runners.py", line 44, in run
    return loop.run_until_complete(main)
  File "/opt/hostedtoolcache/Python/3.8.18/x64/lib/python3.8/asyncio/base_events.py", line 616, in run_until_complete
    return future.result()
  File "/opt/hostedtoolcache/Python/3.8.18/x64/lib/python3.8/site-packages/nanomock/main.py", line 54, in main_async
    await manager.execute_command(args.command, args.nodes, args.payload)
  File "/opt/hostedtoolcache/Python/3.8.18/x64/lib/python3.8/site-packages/nanomock/nanomock_manager.py", line 544, in execute_command
    await command_func(**filtered_command_args)
  File "/opt/hostedtoolcache/Python/3.8.18/x64/lib/python3.8/site-packages/nanomock/internal/utils.py", line 57, in async_wrapper
    result = await func(*args, **kwargs)
  File "/opt/hostedtoolcache/Python/3.8.18/x64/lib/python3.8/site-packages/nanomock/nanomock_manager.py", line 473, in start_containers
    self.docker_interface.compose_start(nodes)
  File "/opt/hostedtoolcache/Python/3.8.18/x64/lib/python3.8/site-packages/nanomock/docker/mixin.py", line 56, in compose_start
    return self._run_command(cmd)
  File "/opt/hostedtoolcache/Python/3.8.18/x64/lib/python3.8/site-packages/nanomock/docker/mixin.py", line 33, in _run_command
    subprocess_run_capture_output(base_command)
  File "/opt/hostedtoolcache/Python/3.8.18/x64/lib/python3.8/site-packages/nanomock/internal/utils.py", line 209, in subprocess_run_capture_output
    raise subprocess.CalledProcessError(
subprocess.CalledProcessError: <exception str() failed>
Connecting to [::ffff:172.17.0.1]:44100
[Errno 111] Connection refused
Connecting to [::ffff:172.17.0.1]:44101
[Errno 111] Connection refused
Connecting to [::ffff:172.17.0.1]:44102
[Errno 111] Connection refused
Connecting to [::ffff:172.17.0.1]:44103
[Errno 111] Connection refused
Connecting to [::ffff:172.17.0.1]:44104
[Errno 111] Connection refused
Connecting to [::ffff:172.17.0.1]:44100
[Errno 111] Connection refused
Connecting to [::ffff:172.17.0.1]:44101
[Errno 111] Connection refused
Connecting to [::ffff:172.17.0.1]:44100
Connecting to [::ffff:172.17.0.1]:44102
[Errno 111] Connection refused
[Errno 111] Connection refused
Connecting to [::ffff:172.17.0.1]:44103
Connecting to [::ffff:172.17.0.1]:44101
[Errno 111] Connection refused
[Errno 111] Connection refused
Connecting to [::ffff:172.17.0.1]:44104
[Errno 111] Connection refused
Connecting to [::ffff:172.17.0.1]:44102
[Errno 111] Connection refused
Connecting to [::ffff:172.17.0.1]:44103
[Errno 111] Connection refused
Connecting to [::ffff:172.17.0.1]:44104
[Errno 111] Connection refused
Connecting to [::ffff:172.17.0.1]:44100
[Errno 111] Connection refused
Connecting to [::ffff:172.17.0.1]:44101
[Errno 111] Connection refused
Connecting to [::ffff:172.17.0.1]:44102
[Errno 111] Connection refused
Exception in thread Thread-1:
Traceback (most recent call last):
  File "/opt/hostedtoolcache/Python/3.8.18/x64/lib/python3.8/threading.py", line 932, in _bootstrap_inner
    self.run()
  File "/opt/hostedtoolcache/Python/3.8.18/x64/lib/python3.8/threading.py", line 870, in run
    self._target(*self._args, **self._kwargs)
  File "/opt/hostedtoolcache/Python/3.8.18/x64/lib/python3.8/site-packages/nanolab/command/command.py", line 49, in execute_another_command
    another_command.execute()
  File "/opt/hostedtoolcache/Python/3.8.18/x64/lib/python3.8/site-packages/nanolab/command/command.py", line 41, in execute
    self.mixin.execute()
  File "/opt/hostedtoolcache/Python/3.8.18/x64/lib/python3.8/site-packages/nanolab/command/mixins/python_command_mixin.py", line 40, in execute
    method(**filtered_variables)
  File "/opt/hostedtoolcache/Python/3.8.18/x64/lib/python3.8/site-packages/nanolab/pycmd.py", line 30, in start_logger
    asyncio.run(nni.start_loggers(logger_params, sink_params))
  File "/opt/hostedtoolcache/Python/3.8.18/x64/lib/python3.8/asyncio/runners.py", line 44, in run
    return loop.run_until_complete(main)
  File "/opt/hostedtoolcache/Python/3.8.18/x64/lib/python3.8/asyncio/base_events.py", line 616, in run_until_complete
    return future.result()
  File "/opt/hostedtoolcache/Python/3.8.18/x64/lib/python3.8/site-packages/nanolab/node_interaction.py", line 17, in start_loggers
    await logger_manager.start_logging()
  File "/opt/hostedtoolcache/Python/3.8.18/x64/lib/python3.8/site-packages/nanolab/loggers/logger_manager.py", line 45, in start_logging
    async for logger, storages in self.create_loggers():
  File "/opt/hostedtoolcache/Python/3.8.18/x64/lib/python3.8/site-packages/nanolab/loggers/logger_manager.py", line 41, in create_loggers
    yield await self.create_logger_and_storages(current_params)
  File "/opt/hostedtoolcache/Python/3.8.18/x64/lib/python3.8/site-packages/nanolab/loggers/logger_manager.py", line 22, in create_logger_and_storages
    logger = await LoggerFactory.create_logger(self.logger_type,
  File "/opt/hostedtoolcache/Python/3.8.18/x64/lib/python3.8/site-packages/nanolab/loggers/factories/logger_factory.py", line 21, in create_logger
    return await builder.build()
  File "/opt/hostedtoolcache/Python/3.8.18/x64/lib/python3.8/site-packages/nanolab/loggers/builders.py", line 44, in build
    await logger.async_init()
  File "/opt/hostedtoolcache/Python/3.8.18/x64/lib/python3.8/site-packages/nanolab/loggers/sources/rpc_logger.py", line 31, in async_init
    self.count_start, self.cemented_start = await self._get_block_count()
  File "/opt/hostedtoolcache/Python/3.8.18/x64/lib/python3.8/site-packages/nanolab/loggers/sources/rpc_logger.py", line 40, in _get_block_count
    block_count = await self.nanorpc.block_count()
  File "/opt/hostedtoolcache/Python/3.8.18/x64/lib/python3.8/site-packages/nanomock/modules/nl_rpc.py", line 37, in block_count
    return await self.nanorpc.block_count(include_cemented=include_cemented)
  File "/opt/hostedtoolcache/Python/3.8.18/x64/lib/python3.8/site-packages/nanorpc/client.py", line 92, in block_count
    return await self.rpc.block_count(include_cemented=include_cemented)
  File "/opt/hostedtoolcache/Python/3.8.18/x64/lib/python3.8/site-packages/nanorpc/client_dynamic.py", line 33, in method
    return await self.process_payloads([payload])
  File "/opt/hostedtoolcache/Python/3.8.18/x64/lib/python3.8/site-packages/nanorpc/client_dynamic.py", line 119, in process_payloads
    return await self._request_with_retry(self._request, payloads)
  File "/opt/hostedtoolcache/Python/3.8.18/x64/lib/python3.8/site-packages/nanorpc/client_dynamic.py", line 101, in _request_with_retry
    return await self._retry_on_exception(coroutine,
  File "/opt/hostedtoolcache/Python/3.8.18/x64/lib/python3.8/site-packages/nanorpc/client_dynamic.py", line 95, in _retry_on_exception
    raise MaxRetriesExceededError(
nanorpc.client_dynamic.MaxRetriesExceededError: All 1 retries exhausted for _request. Last error: Cannot connect to host 172.17.0.1:45101 ssl:default [Connect call failed ('172.17.0.1', 45101)]
Connecting to [::ffff:172.17.0.1]:44103
Connecting to [::ffff:172.17.0.1]:44100
[Errno 111] Connection refused
Connecting to [::ffff:172.17.0.1]:44101
[Errno 111] Connection refused
Connecting to [::ffff:172.17.0.1]:44102
[Errno 111] Connection refused
Connecting to [::ffff:172.17.0.1]:44103
[Errno 111] Connection refused
Connecting to [::ffff:172.17.0.1]:44104
[Errno 111] Connection refused
[Errno 111] Connection refused
Connecting to [::ffff:172.17.0.1]:44104
[Errno 111] Connection refused
Connecting to [::ffff:172.17.0.1]:44100
[Errno 111] Connection refused
Connecting to [::ffff:172.17.0.1]:44101
Connecting to [::ffff:172.17.0.1]:44102
Connecting to [::ffff:172.17.0.1]:44103
Connecting to [::ffff:172.17.0.1]:44104
Error reading from socket (peer: ('::ffff:172.17.0.1', 44104, 0, 0)): timed out
No data from ::ffff:172.17.0.1:44104. Wait 100ms
