Exception in thread Thread-1:
Traceback (most recent call last):
  File "/opt/hostedtoolcache/Python/3.8.18/x64/lib/python3.8/threading.py", line 932, in _bootstrap_inner
    self.run()
  File "/opt/hostedtoolcache/Python/3.8.18/x64/lib/python3.8/threading.py", line 870, in run
    self._target(*self._args, **self._kwargs)
  File "/opt/hostedtoolcache/Python/3.8.18/x64/lib/python3.8/site-packages/nanolab/command/command.py", line 49, in execute_another_command
    another_command.execute()
  File "/opt/hostedtoolcache/Python/3.8.18/x64/lib/python3.8/site-packages/nanolab/command/command.py", line 41, in execute
    self.mixin.execute()
  File "/opt/hostedtoolcache/Python/3.8.18/x64/lib/python3.8/site-packages/nanolab/command/mixins/python_command_mixin.py", line 40, in execute
    method(**filtered_variables)
  File "/opt/hostedtoolcache/Python/3.8.18/x64/lib/python3.8/site-packages/nanolab/pycmd.py", line 30, in start_logger
    asyncio.run(nni.start_loggers(logger_params, sink_params))
  File "/opt/hostedtoolcache/Python/3.8.18/x64/lib/python3.8/asyncio/runners.py", line 44, in run
    return loop.run_until_complete(main)
  File "/opt/hostedtoolcache/Python/3.8.18/x64/lib/python3.8/asyncio/base_events.py", line 616, in run_until_complete
    return future.result()
  File "/opt/hostedtoolcache/Python/3.8.18/x64/lib/python3.8/site-packages/nanolab/node_interaction.py", line 16, in start_loggers
    await logger_manager.start_logging()
  File "/opt/hostedtoolcache/Python/3.8.18/x64/lib/python3.8/site-packages/nanolab/loggers/logger_manager.py", line 45, in start_logging
    async for logger, storages in self.create_loggers():
  File "/opt/hostedtoolcache/Python/3.8.18/x64/lib/python3.8/site-packages/nanolab/loggers/logger_manager.py", line 41, in create_loggers
    yield await self.create_logger_and_storages(current_params)
  File "/opt/hostedtoolcache/Python/3.8.18/x64/lib/python3.8/site-packages/nanolab/loggers/logger_manager.py", line 22, in create_logger_and_storages
    logger = LoggerFactory.create_logger(self.logger_type,
  File "/opt/hostedtoolcache/Python/3.8.18/x64/lib/python3.8/site-packages/nanolab/loggers/factories/logger_factory.py", line 21, in create_logger
    return builder.build()
  File "/opt/hostedtoolcache/Python/3.8.18/x64/lib/python3.8/site-packages/nanolab/loggers/builders.py", line 42, in build
    return RPCLogger(self.node_name, self.rpc_url,
  File "/opt/hostedtoolcache/Python/3.8.18/x64/lib/python3.8/site-packages/nanolab/loggers/sources/rpc_logger.py", line 27, in __init__
    self.count_start, self.cemented_start = self._get_block_count()
  File "/opt/hostedtoolcache/Python/3.8.18/x64/lib/python3.8/site-packages/nanolab/loggers/sources/rpc_logger.py", line 40, in _get_block_count
    return int(block_count["count"]), int(block_count["cemented"])
TypeError: 'NoneType' object is not subscriptable
https://api.github.com/repos/gr0vity-dev/nanolab-configs/contents/quick_testing/5n4pr_conf_10k_change.json
Start Fetching '5n4pr_conf_10k_change_config.json' to '/home/runner/work/nano-node-builder/nano-node-builder/testcases/5n4pr_conf_10k_change_config.json'
Done  Fetching '5n4pr_conf_10k_change_config.json' to '/home/runner/work/nano-node-builder/nano-node-builder/testcases/5n4pr_conf_10k_change_config.json'
Start Fetching '5n4pr_bucket_rounds.json' to '/home/runner/work/nano-node-builder/nano-node-builder/testcases/downloads/5n4pr_bucket_rounds.json'
Done  Fetching '5n4pr_bucket_rounds.json' to '/home/runner/work/nano-node-builder/nano-node-builder/testcases/downloads/5n4pr_bucket_rounds.json'
Start Fetching '5n4pr_bucket0-1-88-90-100_10kaccs.ldb' to '/home/runner/work/nano-node-builder/nano-node-builder/testcases/downloads/5n4pr_bucket0-1-88-90-100_10kaccs.ldb'
Done  Fetching '5n4pr_bucket0-1-88-90-100_10kaccs.ldb' to '/home/runner/work/nano-node-builder/nano-node-builder/testcases/downloads/5n4pr_bucket0-1-88-90-100_10kaccs.ldb'
Start Fetching 'default_5n4pr.toml' to '/home/runner/work/nano-node-builder/nano-node-builder/testcases/downloads/default_5n4pr.toml'
Done  Fetching 'default_5n4pr.toml' to '/home/runner/work/nano-node-builder/nano-node-builder/testcases/downloads/default_5n4pr.toml'
Error executing command: nanomock create && nanomock reset
Error: INFO: nanomock data has been copied to your current working directory.
WARNING: No config-node.toml found. minimal version was created
WARNING: No config-rpc.toml found. minimal version was created
WARNING: No config-node.toml found. minimal version was created
WARNING: No config-rpc.toml found. minimal version was created
WARNING: No config-node.toml found. minimal version was created
WARNING: No config-rpc.toml found. minimal version was created
WARNING: No config-node.toml found. minimal version was created
WARNING: No config-rpc.toml found. minimal version was created
WARNING: No config-node.toml found. minimal version was created
WARNING: No config-rpc.toml found. minimal version was created
SUCCESS: Docker Compose file created at /home/runner/work/nano-node-builder/nano-node-builder/nano_nodes/docker-compose.yml
SUCCESS: 
SUCCESS: stop_containers
SUCCESS: reset_nodes_data
The network 'nl_nano-local' already exists.
Error executing command: nanomock create
Error: INFO: nanomock data has been copied to your current working directory.
WARNING: No config-node.toml found. minimal version was created
WARNING: No config-rpc.toml found. minimal version was created
WARNING: No config-node.toml found. minimal version was created
WARNING: No config-rpc.toml found. minimal version was created
WARNING: No config-node.toml found. minimal version was created
WARNING: No config-rpc.toml found. minimal version was created
WARNING: No config-node.toml found. minimal version was created
WARNING: No config-rpc.toml found. minimal version was created
WARNING: No config-node.toml found. minimal version was created
WARNING: No config-rpc.toml found. minimal version was created
SUCCESS: Docker Compose file created at /home/runner/work/nano-node-builder/nano-node-builder/nano_nodes/docker-compose.yml
SUCCESS:
Error executing command: nanomock start && nanomock init_wallets
Error: Traceback (most recent call last):
  File "/opt/hostedtoolcache/Python/3.8.18/x64/bin/nanomock", line 8, in <module>
    sys.exit(main())
  File "/opt/hostedtoolcache/Python/3.8.18/x64/lib/python3.8/site-packages/nanomock/main.py", line 55, in main
    manager.execute_command(args.command, args.nodes, args.payload)
  File "/opt/hostedtoolcache/Python/3.8.18/x64/lib/python3.8/site-packages/nanomock/nanomock_manager.py", line 488, in execute_command
    command_func(**filtered_command_args)
  File "/opt/hostedtoolcache/Python/3.8.18/x64/lib/python3.8/site-packages/nanomock/internal/utils.py", line 55, in wrapper
    result = func(*args, **kwargs)
  File "/opt/hostedtoolcache/Python/3.8.18/x64/lib/python3.8/site-packages/nanomock/nanomock_manager.py", line 419, in start_containers
    self._wait_for_rpc_availability(nodes)
  File "/opt/hostedtoolcache/Python/3.8.18/x64/lib/python3.8/site-packages/nanomock/nanomock_manager.py", line 276, in _wait_for_rpc_availability
    raise ValueError(
ValueError: TIMEOUT: RPCs not reachable for nodes ['nl_genesis', 'nl_pr1', 'nl_pr2', 'nl_pr3', 'nl_pr4']
Connecting to [::ffff:172.17.0.1]:44100
[Errno 111] Connection refused
Connecting to [::ffff:172.17.0.1]:44101
[Errno 111] Connection refused
Connecting to [::ffff:172.17.0.1]:44102
[Errno 111] Connection refused
Connecting to [::ffff:172.17.0.1]:44103
[Errno 111] Connection refused
Connecting to [::ffff:172.17.0.1]:44104
[Errno 111] Connection refused
