bb0d05436f71a58891d7fec64f1765da570e367e: Pulling from gr0v1ty/nano-node
3713021b0277: Already exists
1a3f61e341bd: Pulling fs layer
0ffb5e7b3048: Pulling fs layer
8fce62962394: Pulling fs layer
dceec86f376c: Pulling fs layer
f5bcb84eec56: Pulling fs layer
0f35c344246f: Pulling fs layer
54268b6046a9: Pulling fs layer
4f4fb700ef54: Pulling fs layer
7918e6bcabfe: Pulling fs layer
cb953529deb0: Pulling fs layer
dceec86f376c: Waiting
f5bcb84eec56: Waiting
0f35c344246f: Waiting
54268b6046a9: Waiting
4f4fb700ef54: Waiting
7918e6bcabfe: Waiting
cb953529deb0: Waiting
1a3f61e341bd: Verifying Checksum
1a3f61e341bd: Download complete
1a3f61e341bd: Pull complete
8fce62962394: Verifying Checksum
8fce62962394: Download complete
dceec86f376c: Verifying Checksum
dceec86f376c: Download complete
f5bcb84eec56: Download complete
0f35c344246f: Verifying Checksum
0f35c344246f: Download complete
54268b6046a9: Verifying Checksum
54268b6046a9: Download complete
4f4fb700ef54: Verifying Checksum
4f4fb700ef54: Download complete
7918e6bcabfe: Verifying Checksum
7918e6bcabfe: Download complete
cb953529deb0: Verifying Checksum
cb953529deb0: Download complete
0ffb5e7b3048: Verifying Checksum
0ffb5e7b3048: Download complete
0ffb5e7b3048: Pull complete
8fce62962394: Pull complete
dceec86f376c: Pull complete
f5bcb84eec56: Pull complete
0f35c344246f: Pull complete
54268b6046a9: Pull complete
4f4fb700ef54: Pull complete
7918e6bcabfe: Pull complete
cb953529deb0: Pull complete
Digest: sha256:924132f0215c5eef3eb070b047178f64e39d3066e04746fdeb534ab4d2f82360
Status: Downloaded newer image for gr0v1ty/nano-node:bb0d05436f71a58891d7fec64f1765da570e367e
docker.io/gr0v1ty/nano-node:bb0d05436f71a58891d7fec64f1765da570e367e
https://api.github.com/repos/gr0vity-dev/nanolab-configs/contents/quick_testing/5n4pr_conf_change_independant.json
Start Fetching '5n4pr_conf_change_independant_config.json' to '/home/runner/work/nano-node-builder/nano-node-builder/testcases/5n4pr_conf_change_independant_config.json'
Done  Fetching '5n4pr_conf_change_independant_config.json' to '/home/runner/work/nano-node-builder/nano-node-builder/testcases/5n4pr_conf_change_independant_config.json'
Start Fetching '5n4pr_bucket0-1-88-90-100_10kaccs.ldb' to '/home/runner/work/nano-node-builder/nano-node-builder/testcases/downloads/5n4pr_bucket0-1-88-90-100_10kaccs.ldb'
Done  Fetching '5n4pr_bucket0-1-88-90-100_10kaccs.ldb' to '/home/runner/work/nano-node-builder/nano-node-builder/testcases/downloads/5n4pr_bucket0-1-88-90-100_10kaccs.ldb'
Start Fetching '5n4pr_quicktesting_config.toml' to '/home/runner/work/nano-node-builder/nano-node-builder/testcases/downloads/5n4pr_quicktesting_config.toml'
Done  Fetching '5n4pr_quicktesting_config.toml' to '/home/runner/work/nano-node-builder/nano-node-builder/testcases/downloads/5n4pr_quicktesting_config.toml'
Error executing command: nanomock conf_edit --payload '{"path" : "remote_address",  "value" : "172.17.0.1"}'
Error: Traceback (most recent call last):
  File "/opt/hostedtoolcache/Python/3.8.18/x64/bin/nanomock", line 8, in <module>
    sys.exit(main())
  File "/opt/hostedtoolcache/Python/3.8.18/x64/lib/python3.8/site-packages/nanomock/main.py", line 58, in main
    asyncio.run(main_async(args))
  File "/opt/hostedtoolcache/Python/3.8.18/x64/lib/python3.8/asyncio/runners.py", line 44, in run
    return loop.run_until_complete(main)
  File "/opt/hostedtoolcache/Python/3.8.18/x64/lib/python3.8/asyncio/base_events.py", line 616, in run_until_complete
    return future.result()
  File "/opt/hostedtoolcache/Python/3.8.18/x64/lib/python3.8/site-packages/nanomock/main.py", line 52, in main_async
    manager = NanoLocalManager(args.path, args.project_name, environ.get(
  File "/opt/hostedtoolcache/Python/3.8.18/x64/lib/python3.8/site-packages/nanomock/nanomock_manager.py", line 32, in __init__
    self.dependency_checker.check_dependencies()
  File "/opt/hostedtoolcache/Python/3.8.18/x64/lib/python3.8/site-packages/nanomock/internal/dependency_checker.py", line 26, in check_dependencies
    if not self._is_dependency_installed(command):
  File "/opt/hostedtoolcache/Python/3.8.18/x64/lib/python3.8/site-packages/nanomock/internal/dependency_checker.py", line 38, in _is_dependency_installed
    subprocess.run(command,
  File "/opt/hostedtoolcache/Python/3.8.18/x64/lib/python3.8/subprocess.py", line 493, in run
    with Popen(*popenargs, **kwargs) as process:
  File "/opt/hostedtoolcache/Python/3.8.18/x64/lib/python3.8/subprocess.py", line 858, in __init__
    self._execute_child(args, executable, preexec_fn, close_fds,
  File "/opt/hostedtoolcache/Python/3.8.18/x64/lib/python3.8/subprocess.py", line 1720, in _execute_child
    raise child_exception_type(errno_num, err_msg, err_filename)
OSError: [Errno 8] Exec format error: 'docker-compose'
Error executing command: nanomock conf_edit --payload '{"path" : "representatives.docker_tag",  "value" : "gr0v1ty/nano-node:bb0d05436f71a58891d7fec64f1765da570e367e"}'
Error: Traceback (most recent call last):
  File "/opt/hostedtoolcache/Python/3.8.18/x64/bin/nanomock", line 8, in <module>
    sys.exit(main())
  File "/opt/hostedtoolcache/Python/3.8.18/x64/lib/python3.8/site-packages/nanomock/main.py", line 58, in main
    asyncio.run(main_async(args))
  File "/opt/hostedtoolcache/Python/3.8.18/x64/lib/python3.8/asyncio/runners.py", line 44, in run
    return loop.run_until_complete(main)
  File "/opt/hostedtoolcache/Python/3.8.18/x64/lib/python3.8/asyncio/base_events.py", line 616, in run_until_complete
    return future.result()
  File "/opt/hostedtoolcache/Python/3.8.18/x64/lib/python3.8/site-packages/nanomock/main.py", line 52, in main_async
    manager = NanoLocalManager(args.path, args.project_name, environ.get(
  File "/opt/hostedtoolcache/Python/3.8.18/x64/lib/python3.8/site-packages/nanomock/nanomock_manager.py", line 32, in __init__
    self.dependency_checker.check_dependencies()
  File "/opt/hostedtoolcache/Python/3.8.18/x64/lib/python3.8/site-packages/nanomock/internal/dependency_checker.py", line 26, in check_dependencies
    if not self._is_dependency_installed(command):
  File "/opt/hostedtoolcache/Python/3.8.18/x64/lib/python3.8/site-packages/nanomock/internal/dependency_checker.py", line 38, in _is_dependency_installed
    subprocess.run(command,
  File "/opt/hostedtoolcache/Python/3.8.18/x64/lib/python3.8/subprocess.py", line 493, in run
    with Popen(*popenargs, **kwargs) as process:
  File "/opt/hostedtoolcache/Python/3.8.18/x64/lib/python3.8/subprocess.py", line 858, in __init__
    self._execute_child(args, executable, preexec_fn, close_fds,
  File "/opt/hostedtoolcache/Python/3.8.18/x64/lib/python3.8/subprocess.py", line 1720, in _execute_child
    raise child_exception_type(errno_num, err_msg, err_filename)
OSError: [Errno 8] Exec format error: 'docker-compose'
Error executing command: nanomock create && nanomock reset
Error: Traceback (most recent call last):
  File "/opt/hostedtoolcache/Python/3.8.18/x64/bin/nanomock", line 8, in <module>
    sys.exit(main())
  File "/opt/hostedtoolcache/Python/3.8.18/x64/lib/python3.8/site-packages/nanomock/main.py", line 58, in main
    asyncio.run(main_async(args))
  File "/opt/hostedtoolcache/Python/3.8.18/x64/lib/python3.8/asyncio/runners.py", line 44, in run
    return loop.run_until_complete(main)
  File "/opt/hostedtoolcache/Python/3.8.18/x64/lib/python3.8/asyncio/base_events.py", line 616, in run_until_complete
    return future.result()
  File "/opt/hostedtoolcache/Python/3.8.18/x64/lib/python3.8/site-packages/nanomock/main.py", line 52, in main_async
    manager = NanoLocalManager(args.path, args.project_name, environ.get(
  File "/opt/hostedtoolcache/Python/3.8.18/x64/lib/python3.8/site-packages/nanomock/nanomock_manager.py", line 32, in __init__
    self.dependency_checker.check_dependencies()
  File "/opt/hostedtoolcache/Python/3.8.18/x64/lib/python3.8/site-packages/nanomock/internal/dependency_checker.py", line 26, in check_dependencies
    if not self._is_dependency_installed(command):
  File "/opt/hostedtoolcache/Python/3.8.18/x64/lib/python3.8/site-packages/nanomock/internal/dependency_checker.py", line 38, in _is_dependency_installed
    subprocess.run(command,
  File "/opt/hostedtoolcache/Python/3.8.18/x64/lib/python3.8/subprocess.py", line 493, in run
    with Popen(*popenargs, **kwargs) as process:
  File "/opt/hostedtoolcache/Python/3.8.18/x64/lib/python3.8/subprocess.py", line 858, in __init__
    self._execute_child(args, executable, preexec_fn, close_fds,
  File "/opt/hostedtoolcache/Python/3.8.18/x64/lib/python3.8/subprocess.py", line 1720, in _execute_child
    raise child_exception_type(errno_num, err_msg, err_filename)
OSError: [Errno 8] Exec format error: 'docker-compose'
Error executing command: for i in nl_genesis nl_pr1 nl_pr2 nl_pr3 nl_pr4; do if [ "" = true ]; then rm -rf ./nano_nodes/$i/NanoTest/rocksdb && if echo /home/runner/work/nano-node-builder/nano-node-builder/testcases/downloads/5n4pr_bucket0-1-88-90-100_10kaccs.ldb | grep -q '.tar.gz' ; then mkdir -p ./nano_nodes/$i/NanoTest/rocksdb && tar --strip-components=1 -xzf /home/runner/work/nano-node-builder/nano-node-builder/testcases/downloads/5n4pr_bucket0-1-88-90-100_10kaccs.ldb -C ./nano_nodes/$i/NanoTest/rocksdb; else cp -r /home/runner/work/nano-node-builder/nano-node-builder/testcases/downloads/5n4pr_bucket0-1-88-90-100_10kaccs.ldb ./nano_nodes/$i/NanoTest/rocksdb;fi; else cp /home/runner/work/nano-node-builder/nano-node-builder/testcases/downloads/5n4pr_bucket0-1-88-90-100_10kaccs.ldb ./nano_nodes/$i/NanoTest/data.ldb; fi; done
Error: cp: cannot create regular file './nano_nodes/nl_genesis/NanoTest/data.ldb': No such file or directory
cp: cannot create regular file './nano_nodes/nl_pr1/NanoTest/data.ldb': No such file or directory
cp: cannot create regular file './nano_nodes/nl_pr2/NanoTest/data.ldb': No such file or directory
cp: cannot create regular file './nano_nodes/nl_pr3/NanoTest/data.ldb': No such file or directory
cp: cannot create regular file './nano_nodes/nl_pr4/NanoTest/data.ldb': No such file or directory
Error executing command: nanomock conf_edit --payload '{"path" : "promexporter_enable",  "value" : "false"}'
Error: Traceback (most recent call last):
  File "/opt/hostedtoolcache/Python/3.8.18/x64/bin/nanomock", line 8, in <module>
    sys.exit(main())
  File "/opt/hostedtoolcache/Python/3.8.18/x64/lib/python3.8/site-packages/nanomock/main.py", line 58, in main
    asyncio.run(main_async(args))
  File "/opt/hostedtoolcache/Python/3.8.18/x64/lib/python3.8/asyncio/runners.py", line 44, in run
    return loop.run_until_complete(main)
  File "/opt/hostedtoolcache/Python/3.8.18/x64/lib/python3.8/asyncio/base_events.py", line 616, in run_until_complete
    return future.result()
  File "/opt/hostedtoolcache/Python/3.8.18/x64/lib/python3.8/site-packages/nanomock/main.py", line 52, in main_async
    manager = NanoLocalManager(args.path, args.project_name, environ.get(
  File "/opt/hostedtoolcache/Python/3.8.18/x64/lib/python3.8/site-packages/nanomock/nanomock_manager.py", line 32, in __init__
    self.dependency_checker.check_dependencies()
  File "/opt/hostedtoolcache/Python/3.8.18/x64/lib/python3.8/site-packages/nanomock/internal/dependency_checker.py", line 26, in check_dependencies
    if not self._is_dependency_installed(command):
  File "/opt/hostedtoolcache/Python/3.8.18/x64/lib/python3.8/site-packages/nanomock/internal/dependency_checker.py", line 38, in _is_dependency_installed
    subprocess.run(command,
  File "/opt/hostedtoolcache/Python/3.8.18/x64/lib/python3.8/subprocess.py", line 493, in run
    with Popen(*popenargs, **kwargs) as process:
  File "/opt/hostedtoolcache/Python/3.8.18/x64/lib/python3.8/subprocess.py", line 858, in __init__
    self._execute_child(args, executable, preexec_fn, close_fds,
  File "/opt/hostedtoolcache/Python/3.8.18/x64/lib/python3.8/subprocess.py", line 1720, in _execute_child
    raise child_exception_type(errno_num, err_msg, err_filename)
OSError: [Errno 8] Exec format error: 'docker-compose'
Error executing command: nanomock conf_edit --payload '{"path" : "representatives.cpu",  "value" : "0.3"}'
Error: Traceback (most recent call last):
  File "/opt/hostedtoolcache/Python/3.8.18/x64/bin/nanomock", line 8, in <module>
    sys.exit(main())
  File "/opt/hostedtoolcache/Python/3.8.18/x64/lib/python3.8/site-packages/nanomock/main.py", line 58, in main
    asyncio.run(main_async(args))
  File "/opt/hostedtoolcache/Python/3.8.18/x64/lib/python3.8/asyncio/runners.py", line 44, in run
    return loop.run_until_complete(main)
  File "/opt/hostedtoolcache/Python/3.8.18/x64/lib/python3.8/asyncio/base_events.py", line 616, in run_until_complete
    return future.result()
  File "/opt/hostedtoolcache/Python/3.8.18/x64/lib/python3.8/site-packages/nanomock/main.py", line 52, in main_async
    manager = NanoLocalManager(args.path, args.project_name, environ.get(
  File "/opt/hostedtoolcache/Python/3.8.18/x64/lib/python3.8/site-packages/nanomock/nanomock_manager.py", line 32, in __init__
    self.dependency_checker.check_dependencies()
  File "/opt/hostedtoolcache/Python/3.8.18/x64/lib/python3.8/site-packages/nanomock/internal/dependency_checker.py", line 26, in check_dependencies
    if not self._is_dependency_installed(command):
  File "/opt/hostedtoolcache/Python/3.8.18/x64/lib/python3.8/site-packages/nanomock/internal/dependency_checker.py", line 38, in _is_dependency_installed
    subprocess.run(command,
  File "/opt/hostedtoolcache/Python/3.8.18/x64/lib/python3.8/subprocess.py", line 493, in run
    with Popen(*popenargs, **kwargs) as process:
  File "/opt/hostedtoolcache/Python/3.8.18/x64/lib/python3.8/subprocess.py", line 858, in __init__
    self._execute_child(args, executable, preexec_fn, close_fds,
  File "/opt/hostedtoolcache/Python/3.8.18/x64/lib/python3.8/subprocess.py", line 1720, in _execute_child
    raise child_exception_type(errno_num, err_msg, err_filename)
OSError: [Errno 8] Exec format error: 'docker-compose'
Error executing command: nanomock create
Error: Traceback (most recent call last):
  File "/opt/hostedtoolcache/Python/3.8.18/x64/bin/nanomock", line 8, in <module>
    sys.exit(main())
  File "/opt/hostedtoolcache/Python/3.8.18/x64/lib/python3.8/site-packages/nanomock/main.py", line 58, in main
    asyncio.run(main_async(args))
  File "/opt/hostedtoolcache/Python/3.8.18/x64/lib/python3.8/asyncio/runners.py", line 44, in run
    return loop.run_until_complete(main)
  File "/opt/hostedtoolcache/Python/3.8.18/x64/lib/python3.8/asyncio/base_events.py", line 616, in run_until_complete
    return future.result()
  File "/opt/hostedtoolcache/Python/3.8.18/x64/lib/python3.8/site-packages/nanomock/main.py", line 52, in main_async
    manager = NanoLocalManager(args.path, args.project_name, environ.get(
  File "/opt/hostedtoolcache/Python/3.8.18/x64/lib/python3.8/site-packages/nanomock/nanomock_manager.py", line 32, in __init__
    self.dependency_checker.check_dependencies()
  File "/opt/hostedtoolcache/Python/3.8.18/x64/lib/python3.8/site-packages/nanomock/internal/dependency_checker.py", line 26, in check_dependencies
    if not self._is_dependency_installed(command):
  File "/opt/hostedtoolcache/Python/3.8.18/x64/lib/python3.8/site-packages/nanomock/internal/dependency_checker.py", line 38, in _is_dependency_installed
    subprocess.run(command,
  File "/opt/hostedtoolcache/Python/3.8.18/x64/lib/python3.8/subprocess.py", line 493, in run
    with Popen(*popenargs, **kwargs) as process:
  File "/opt/hostedtoolcache/Python/3.8.18/x64/lib/python3.8/subprocess.py", line 858, in __init__
    self._execute_child(args, executable, preexec_fn, close_fds,
  File "/opt/hostedtoolcache/Python/3.8.18/x64/lib/python3.8/subprocess.py", line 1720, in _execute_child
    raise child_exception_type(errno_num, err_msg, err_filename)
OSError: [Errno 8] Exec format error: 'docker-compose'
Exception in thread Thread-1:
Traceback (most recent call last):
  File "/opt/hostedtoolcache/Python/3.8.18/x64/lib/python3.8/threading.py", line 932, in _bootstrap_inner
    self.run()
  File "/opt/hostedtoolcache/Python/3.8.18/x64/lib/python3.8/threading.py", line 870, in run
    self._target(*self._args, **self._kwargs)
  File "/opt/hostedtoolcache/Python/3.8.18/x64/lib/python3.8/site-packages/nanolab/command/mixins/threaded_command_mixin.py", line 26, in _execute_command_sequence
    self.command_instance.execute_another_command(command_config)
  File "/opt/hostedtoolcache/Python/3.8.18/x64/lib/python3.8/site-packages/nanolab/command/command.py", line 49, in execute_another_command
    another_command.execute()
  File "/opt/hostedtoolcache/Python/3.8.18/x64/lib/python3.8/site-packages/nanolab/command/command.py", line 41, in execute
    self.mixin.execute()
  File "/opt/hostedtoolcache/Python/3.8.18/x64/lib/python3.8/site-packages/nanolab/command/mixins/python_command_mixin.py", line 40, in execute
    method(**filtered_variables)
  File "/opt/hostedtoolcache/Python/3.8.18/x64/lib/python3.8/site-packages/nanolab/pycmd.py", line 35, in publish_create
    asyncio.run(test_case.run())
  File "/opt/hostedtoolcache/Python/3.8.18/x64/lib/python3.8/asyncio/runners.py", line 44, in run
    return loop.run_until_complete(main)
  File "/opt/hostedtoolcache/Python/3.8.18/x64/lib/python3.8/asyncio/base_events.py", line 616, in run_until_complete
    return future.result()
  File "/opt/hostedtoolcache/Python/3.8.18/x64/lib/python3.8/site-packages/nanolab/publisher/test_case.py", line 69, in run
    await self.stats_manager.initialize(self.node_name)
  File "/opt/hostedtoolcache/Python/3.8.18/x64/lib/python3.8/site-packages/nanolab/publisher/confirmation_stats.py", line 17, in initialize
    start_block_count = await self.nanorpc.block_count()
  File "/opt/hostedtoolcache/Python/3.8.18/x64/lib/python3.8/site-packages/nanorpc/client.py", line 50, in block_count
    return await self.rpc.block_count(include_cemented=include_cemented)
  File "/opt/hostedtoolcache/Python/3.8.18/x64/lib/python3.8/site-packages/nanorpc/client_dynamic.py", line 33, in method
    return await self.process_payloads([payload])
  File "/opt/hostedtoolcache/Python/3.8.18/x64/lib/python3.8/site-packages/nanorpc/client_dynamic.py", line 119, in process_payloads
    return await self._request_with_retry(self._request, payloads)
  File "/opt/hostedtoolcache/Python/3.8.18/x64/lib/python3.8/site-packages/nanorpc/client_dynamic.py", line 101, in _request_with_retry
    return await self._retry_on_exception(coroutine,
  File "/opt/hostedtoolcache/Python/3.8.18/x64/lib/python3.8/site-packages/nanorpc/client_dynamic.py", line 95, in _retry_on_exception
    raise MaxRetriesExceededError(
nanorpc.client_dynamic.MaxRetriesExceededError: All 1 retries exhausted for _request. Last error: Cannot connect to host 172.17.0.1:45101 ssl:default [Connect call failed ('172.17.0.1', 45101)]
Error executing command: nanomock start && nanomock init_wallets
Error: Traceback (most recent call last):
  File "/opt/hostedtoolcache/Python/3.8.18/x64/bin/nanomock", line 8, in <module>
    sys.exit(main())
  File "/opt/hostedtoolcache/Python/3.8.18/x64/lib/python3.8/site-packages/nanomock/main.py", line 58, in main
    asyncio.run(main_async(args))
  File "/opt/hostedtoolcache/Python/3.8.18/x64/lib/python3.8/asyncio/runners.py", line 44, in run
    return loop.run_until_complete(main)
  File "/opt/hostedtoolcache/Python/3.8.18/x64/lib/python3.8/asyncio/base_events.py", line 616, in run_until_complete
    return future.result()
  File "/opt/hostedtoolcache/Python/3.8.18/x64/lib/python3.8/site-packages/nanomock/main.py", line 52, in main_async
    manager = NanoLocalManager(args.path, args.project_name, environ.get(
  File "/opt/hostedtoolcache/Python/3.8.18/x64/lib/python3.8/site-packages/nanomock/nanomock_manager.py", line 32, in __init__
    self.dependency_checker.check_dependencies()
  File "/opt/hostedtoolcache/Python/3.8.18/x64/lib/python3.8/site-packages/nanomock/internal/dependency_checker.py", line 26, in check_dependencies
    if not self._is_dependency_installed(command):
  File "/opt/hostedtoolcache/Python/3.8.18/x64/lib/python3.8/site-packages/nanomock/internal/dependency_checker.py", line 38, in _is_dependency_installed
    subprocess.run(command,
  File "/opt/hostedtoolcache/Python/3.8.18/x64/lib/python3.8/subprocess.py", line 493, in run
    with Popen(*popenargs, **kwargs) as process:
  File "/opt/hostedtoolcache/Python/3.8.18/x64/lib/python3.8/subprocess.py", line 858, in __init__
    self._execute_child(args, executable, preexec_fn, close_fds,
  File "/opt/hostedtoolcache/Python/3.8.18/x64/lib/python3.8/subprocess.py", line 1720, in _execute_child
    raise child_exception_type(errno_num, err_msg, err_filename)
OSError: [Errno 8] Exec format error: 'docker-compose'
