e8f8e581c4531366517261feb85c39ffd78b121f: Pulling from gr0v1ty/nano-node
89dc6ea4eae2: Pulling fs layer
1cf61e1771fe: Pulling fs layer
ece1241de590: Pulling fs layer
5982ef8e2a6c: Pulling fs layer
2975e021f739: Pulling fs layer
3778d0e4ce75: Pulling fs layer
83ef34152516: Pulling fs layer
b23f9562f49a: Pulling fs layer
4f4fb700ef54: Pulling fs layer
c2ecd8424950: Pulling fs layer
a393e006f6eb: Pulling fs layer
5982ef8e2a6c: Waiting
2975e021f739: Waiting
3778d0e4ce75: Waiting
83ef34152516: Waiting
b23f9562f49a: Waiting
4f4fb700ef54: Waiting
a393e006f6eb: Waiting
c2ecd8424950: Waiting
89dc6ea4eae2: Verifying Checksum
89dc6ea4eae2: Download complete
1cf61e1771fe: Verifying Checksum
1cf61e1771fe: Download complete
89dc6ea4eae2: Pull complete
2975e021f739: Verifying Checksum
2975e021f739: Download complete
1cf61e1771fe: Pull complete
5982ef8e2a6c: Verifying Checksum
5982ef8e2a6c: Download complete
3778d0e4ce75: Verifying Checksum
3778d0e4ce75: Download complete
83ef34152516: Download complete
4f4fb700ef54: Verifying Checksum
4f4fb700ef54: Download complete
b23f9562f49a: Verifying Checksum
b23f9562f49a: Download complete
c2ecd8424950: Verifying Checksum
c2ecd8424950: Download complete
a393e006f6eb: Verifying Checksum
a393e006f6eb: Download complete
ece1241de590: Download complete
ece1241de590: Pull complete
5982ef8e2a6c: Pull complete
2975e021f739: Pull complete
3778d0e4ce75: Pull complete
83ef34152516: Pull complete
b23f9562f49a: Pull complete
4f4fb700ef54: Pull complete
c2ecd8424950: Pull complete
a393e006f6eb: Pull complete
Digest: sha256:0a571fa49b4ec219a45c1ff3eeb5951bdf4d0a5de4f71b24cb89af5172ffc9e8
Status: Downloaded newer image for gr0v1ty/nano-node:e8f8e581c4531366517261feb85c39ffd78b121f
docker.io/gr0v1ty/nano-node:e8f8e581c4531366517261feb85c39ffd78b121f
Exception in thread Thread-1:
Traceback (most recent call last):
  File "/opt/hostedtoolcache/Python/3.8.18/x64/lib/python3.8/asyncio/selector_events.py", line 848, in _read_ready__data_received
    data = self._sock.recv(self.max_size)
ConnectionResetError: [Errno 104] Connection reset by peer

The above exception was the direct cause of the following exception:

Traceback (most recent call last):
  File "/opt/hostedtoolcache/Python/3.8.18/x64/lib/python3.8/threading.py", line 932, in _bootstrap_inner
    self.run()
  File "/opt/hostedtoolcache/Python/3.8.18/x64/lib/python3.8/threading.py", line 870, in run
    self._target(*self._args, **self._kwargs)
  File "/opt/hostedtoolcache/Python/3.8.18/x64/lib/python3.8/site-packages/nanolab/command/command.py", line 49, in execute_another_command
    another_command.execute()
  File "/opt/hostedtoolcache/Python/3.8.18/x64/lib/python3.8/site-packages/nanolab/command/command.py", line 41, in execute
    self.mixin.execute()
  File "/opt/hostedtoolcache/Python/3.8.18/x64/lib/python3.8/site-packages/nanolab/command/mixins/python_command_mixin.py", line 40, in execute
    method(**filtered_variables)
  File "/opt/hostedtoolcache/Python/3.8.18/x64/lib/python3.8/site-packages/nanolab/pycmd.py", line 30, in start_logger
    asyncio.run(nni.start_loggers(logger_params, sink_params))
  File "/opt/hostedtoolcache/Python/3.8.18/x64/lib/python3.8/asyncio/runners.py", line 44, in run
    return loop.run_until_complete(main)
  File "/opt/hostedtoolcache/Python/3.8.18/x64/lib/python3.8/asyncio/base_events.py", line 616, in run_until_complete
    return future.result()
  File "/opt/hostedtoolcache/Python/3.8.18/x64/lib/python3.8/site-packages/nanolab/node_interaction.py", line 17, in start_loggers
    await logger_manager.start_logging()
  File "/opt/hostedtoolcache/Python/3.8.18/x64/lib/python3.8/site-packages/nanolab/loggers/logger_manager.py", line 45, in start_logging
    async for logger, storages in self.create_loggers():
  File "/opt/hostedtoolcache/Python/3.8.18/x64/lib/python3.8/site-packages/nanolab/loggers/logger_manager.py", line 41, in create_loggers
    yield await self.create_logger_and_storages(current_params)
  File "/opt/hostedtoolcache/Python/3.8.18/x64/lib/python3.8/site-packages/nanolab/loggers/logger_manager.py", line 22, in create_logger_and_storages
    logger = await LoggerFactory.create_logger(self.logger_type,
  File "/opt/hostedtoolcache/Python/3.8.18/x64/lib/python3.8/site-packages/nanolab/loggers/factories/logger_factory.py", line 21, in create_logger
    return await builder.build()
  File "/opt/hostedtoolcache/Python/3.8.18/x64/lib/python3.8/site-packages/nanolab/loggers/builders.py", line 44, in build
    await logger.async_init()
  File "/opt/hostedtoolcache/Python/3.8.18/x64/lib/python3.8/site-packages/nanolab/loggers/sources/rpc_logger.py", line 31, in async_init
    self.count_start, self.cemented_start = await self._get_block_count()
  File "/opt/hostedtoolcache/Python/3.8.18/x64/lib/python3.8/site-packages/nanolab/loggers/sources/rpc_logger.py", line 40, in _get_block_count
    block_count = await self.nanorpc.block_count()
  File "/opt/hostedtoolcache/Python/3.8.18/x64/lib/python3.8/site-packages/nanomock/modules/nl_rpc.py", line 37, in block_count
    return await self.nanorpc.block_count(include_cemented=include_cemented)
  File "/opt/hostedtoolcache/Python/3.8.18/x64/lib/python3.8/site-packages/nanorpc/client.py", line 92, in block_count
    return await self.rpc.block_count(include_cemented=include_cemented)
  File "/opt/hostedtoolcache/Python/3.8.18/x64/lib/python3.8/site-packages/nanorpc/client_dynamic.py", line 33, in method
    return await self.process_payloads([payload])
  File "/opt/hostedtoolcache/Python/3.8.18/x64/lib/python3.8/site-packages/nanorpc/client_dynamic.py", line 119, in process_payloads
    return await self._request_with_retry(self._request, payloads)
  File "/opt/hostedtoolcache/Python/3.8.18/x64/lib/python3.8/site-packages/nanorpc/client_dynamic.py", line 101, in _request_with_retry
    return await self._retry_on_exception(coroutine,
  File "/opt/hostedtoolcache/Python/3.8.18/x64/lib/python3.8/site-packages/nanorpc/client_dynamic.py", line 92, in _retry_on_exception
    return await coroutine(*args)
  File "/opt/hostedtoolcache/Python/3.8.18/x64/lib/python3.8/site-packages/nanorpc/client_dynamic.py", line 108, in _request
    async with session.post(self.url, json=payloads[0], headers=self.headers) as response:
  File "/opt/hostedtoolcache/Python/3.8.18/x64/lib/python3.8/site-packages/aiohttp/client.py", line 1360, in __aenter__
    self._resp: _RetType = await self._coro
  File "/opt/hostedtoolcache/Python/3.8.18/x64/lib/python3.8/site-packages/aiohttp/client.py", line 690, in _request
    await resp.start(conn)
  File "/opt/hostedtoolcache/Python/3.8.18/x64/lib/python3.8/site-packages/aiohttp/client_reqrep.py", line 1059, in start
    message, payload = await protocol.read()  # type: ignore[union-attr]
  File "/opt/hostedtoolcache/Python/3.8.18/x64/lib/python3.8/site-packages/aiohttp/streams.py", line 644, in read
    await self._waiter
aiohttp.client_exceptions.ClientOSError: [Errno 104] Connection reset by peer
https://api.github.com/repos/gr0vity-dev/nanolab-configs/contents/quick_testing/5n4pr_conf_10k_change.json
Start Fetching '5n4pr_conf_10k_change_config.json' to '/home/runner/work/nano-node-builder/nano-node-builder/testcases/5n4pr_conf_10k_change_config.json'
Done  Fetching '5n4pr_conf_10k_change_config.json' to '/home/runner/work/nano-node-builder/nano-node-builder/testcases/5n4pr_conf_10k_change_config.json'
Start Fetching '5n4pr_bucket_rounds_short.json' to '/home/runner/work/nano-node-builder/nano-node-builder/testcases/downloads/5n4pr_bucket_rounds_short.json'
Done  Fetching '5n4pr_bucket_rounds_short.json' to '/home/runner/work/nano-node-builder/nano-node-builder/testcases/downloads/5n4pr_bucket_rounds_short.json'
Start Fetching '5n4pr_bucket0-1-88-90-100_10kaccs.ldb' to '/home/runner/work/nano-node-builder/nano-node-builder/testcases/downloads/5n4pr_bucket0-1-88-90-100_10kaccs.ldb'
Done  Fetching '5n4pr_bucket0-1-88-90-100_10kaccs.ldb' to '/home/runner/work/nano-node-builder/nano-node-builder/testcases/downloads/5n4pr_bucket0-1-88-90-100_10kaccs.ldb'
Start Fetching '5n4pr_quicktesting_config.toml' to '/home/runner/work/nano-node-builder/nano-node-builder/testcases/downloads/5n4pr_quicktesting_config.toml'
Done  Fetching '5n4pr_quicktesting_config.toml' to '/home/runner/work/nano-node-builder/nano-node-builder/testcases/downloads/5n4pr_quicktesting_config.toml'
Start Fetching 'config-node_5n4pr_spam_buffer.toml' to '/home/runner/work/nano-node-builder/nano-node-builder/testcases/downloads/config-node_5n4pr_spam_buffer.toml'
Done  Fetching 'config-node_5n4pr_spam_buffer.toml' to '/home/runner/work/nano-node-builder/nano-node-builder/testcases/downloads/config-node_5n4pr_spam_buffer.toml'
Error executing command: nanomock create && nanomock reset
Error: INFO: nanomock data has been copied to your current working directory.
INFO: Log level : default
INFO: Log level : default
INFO: Log level : default
INFO: Log level : default
INFO: Log level : default
SUCCESS: Docker Compose file created at /home/runner/work/nano-node-builder/nano-node-builder/nano_nodes/docker-compose.yml
SUCCESS: None
SUCCESS: init_containers completed with None result.
SUCCESS: stop_containers completed with None result.
SUCCESS: reset_nodes_data completed with None result.
The network 'nl_nano-local' already exists.
Error executing command: nanomock create
Error: INFO: nanomock data has been copied to your current working directory.
INFO: Log level : default
INFO: Log level : default
INFO: Log level : default
INFO: Log level : default
INFO: Log level : default
SUCCESS: Docker Compose file created at /home/runner/work/nano-node-builder/nano-node-builder/nano_nodes/docker-compose.yml
SUCCESS: None
SUCCESS: init_containers completed with None result.
Error executing command: nanomock start && nanomock init_wallets
Error: WARNING: ['nl_genesis', 'nl_pr1', 'nl_pr2', 'nl_pr3', 'nl_pr4']
INFO: Nodes ['nl_genesis', 'nl_pr1', 'nl_pr2', 'nl_pr3', 'nl_pr4'] reachable
SUCCESS: start_containers completed with None result.
WARNING: ['nl_genesis']
WARNING: ['nl_pr1']
WARNING: ['nl_pr2']
WARNING: ['nl_pr3']
WARNING: ['nl_pr4']
INFO: Nodes ['nl_genesis'] reachable
INFO: Nodes ['nl_pr1'] reachable
INFO: Nodes ['nl_pr2'] reachable
INFO: Nodes ['nl_pr3'] reachable
INFO: Nodes ['nl_pr4'] reachable
Traceback (most recent call last):
  File "/opt/hostedtoolcache/Python/3.8.18/x64/bin/nanomock", line 8, in <module>
    sys.exit(main())
  File "/opt/hostedtoolcache/Python/3.8.18/x64/lib/python3.8/site-packages/nanomock/main.py", line 58, in main
    asyncio.run(main_async(args))
  File "/opt/hostedtoolcache/Python/3.8.18/x64/lib/python3.8/asyncio/runners.py", line 44, in run
    return loop.run_until_complete(main)
  File "/opt/hostedtoolcache/Python/3.8.18/x64/lib/python3.8/asyncio/base_events.py", line 616, in run_until_complete
    return future.result()
  File "/opt/hostedtoolcache/Python/3.8.18/x64/lib/python3.8/site-packages/nanomock/main.py", line 54, in main_async
    await manager.execute_command(args.command, args.nodes, args.payload)
  File "/opt/hostedtoolcache/Python/3.8.18/x64/lib/python3.8/site-packages/nanomock/nanomock_manager.py", line 544, in execute_command
    await command_func(**filtered_command_args)
  File "/opt/hostedtoolcache/Python/3.8.18/x64/lib/python3.8/site-packages/nanomock/internal/utils.py", line 57, in async_wrapper
    result = await func(*args, **kwargs)
  File "/opt/hostedtoolcache/Python/3.8.18/x64/lib/python3.8/site-packages/nanomock/nanomock_manager.py", line 404, in init_wallets
    await asyncio.gather(*(process_node(node_name) for node_name in node_names))
  File "/opt/hostedtoolcache/Python/3.8.18/x64/lib/python3.8/site-packages/nanomock/nanomock_manager.py", line 398, in process_node
    await init_blocks.create_node_wallet(
  File "/opt/hostedtoolcache/Python/3.8.18/x64/lib/python3.8/site-packages/nanomock/internal/nl_initialise.py", line 202, in create_node_wallet
    wallet = await node_rpc.wallet_create(seed=seed)
  File "/opt/hostedtoolcache/Python/3.8.18/x64/lib/python3.8/site-packages/nanomock/modules/nl_rpc.py", line 73, in wallet_create
    return await self.nanorpc.wallet_create(seed=seed)
  File "/opt/hostedtoolcache/Python/3.8.18/x64/lib/python3.8/site-packages/nanorpc/client.py", line 348, in wallet_create
    return await self.rpc.wallet_create(seed=seed)
  File "/opt/hostedtoolcache/Python/3.8.18/x64/lib/python3.8/site-packages/nanorpc/client_dynamic.py", line 33, in method
    return await self.process_payloads([payload])
  File "/opt/hostedtoolcache/Python/3.8.18/x64/lib/python3.8/site-packages/nanorpc/client_dynamic.py", line 119, in process_payloads
    return await self._request_with_retry(self._request, payloads)
  File "/opt/hostedtoolcache/Python/3.8.18/x64/lib/python3.8/site-packages/nanorpc/client_dynamic.py", line 101, in _request_with_retry
    return await self._retry_on_exception(coroutine,
  File "/opt/hostedtoolcache/Python/3.8.18/x64/lib/python3.8/site-packages/nanorpc/client_dynamic.py", line 92, in _retry_on_exception
    return await coroutine(*args)
  File "/opt/hostedtoolcache/Python/3.8.18/x64/lib/python3.8/site-packages/nanorpc/client_dynamic.py", line 108, in _request
    async with session.post(self.url, json=payloads[0], headers=self.headers) as response:
  File "/opt/hostedtoolcache/Python/3.8.18/x64/lib/python3.8/site-packages/aiohttp/client.py", line 1360, in __aenter__
    self._resp: _RetType = await self._coro
  File "/opt/hostedtoolcache/Python/3.8.18/x64/lib/python3.8/site-packages/aiohttp/client.py", line 690, in _request
    await resp.start(conn)
  File "/opt/hostedtoolcache/Python/3.8.18/x64/lib/python3.8/site-packages/aiohttp/client_reqrep.py", line 1059, in start
    message, payload = await protocol.read()  # type: ignore[union-attr]
  File "/opt/hostedtoolcache/Python/3.8.18/x64/lib/python3.8/site-packages/aiohttp/streams.py", line 644, in read
    await self._waiter
aiohttp.client_exceptions.ServerDisconnectedError: Server disconnected
Connecting to [::ffff:172.17.0.1]:44100
Connecting to [::ffff:172.17.0.1]:44100
Connecting to [::ffff:172.17.0.1]:44100
Connecting to [::ffff:172.17.0.1]:44100
Connecting to [::ffff:172.17.0.1]:44100
read_socket] Error reading 136 bytes, data=, msg=[Errno 104] Connection reset by peer
HandshakeExchangeFail
Connecting to [::ffff:172.17.0.1]:44101
[Errno 111] Connection refused
Connecting to [::ffff:172.17.0.1]:44102
[Errno 111] Connection refused
Connecting to [::ffff:172.17.0.1]:44103
[Errno 111] Connection refused
Connecting to [::ffff:172.17.0.1]:44104
[Errno 111] Connection refused
read_socket] Error reading 136 bytes, data=, msg=[Errno 104] Connection reset by peer
HandshakeExchangeFail
read_socket] Error reading 136 bytes, data=, msg=[Errno 104] Connection reset by peer
HandshakeExchangeFail
Connecting to [::ffff:172.17.0.1]:44101
read_socket] Error reading 136 bytes, data=, msg=[Errno 104] Connection reset by peer
HandshakeExchangeFail
Connecting to [::ffff:172.17.0.1]:44101
[Errno 111] Connection refused
Connecting to [::ffff:172.17.0.1]:44102
[Errno 111] Connection refused
Connecting to [::ffff:172.17.0.1]:44103
[Errno 111] Connection refused
read_socket] Error reading 136 bytes, data=, msg=[Errno 104] Connection reset by peer
HandshakeExchangeFail
Connecting to [::ffff:172.17.0.1]:44101
[Errno 111] Connection refused
Connecting to [::ffff:172.17.0.1]:44102
[Errno 111] Connection refused
Connecting to [::ffff:172.17.0.1]:44103
[Errno 111] Connection refused
Connecting to [::ffff:172.17.0.1]:44104
[Errno 111] Connection refused
Connecting to [::ffff:172.17.0.1]:44104
[Errno 111] Connection refused
Connecting to [::ffff:172.17.0.1]:44101
[Errno 111] Connection refused
Connecting to [::ffff:172.17.0.1]:44102
[Errno 111] Connection refused
Connecting to [::ffff:172.17.0.1]:44103
[Errno 111] Connection refused
Connecting to [::ffff:172.17.0.1]:44104
[Errno 111] Connection refused
[Errno 111] Connection refused
Connecting to [::ffff:172.17.0.1]:44102
[Errno 111] Connection refused
Connecting to [::ffff:172.17.0.1]:44103
[Errno 111] Connection refused
Connecting to [::ffff:172.17.0.1]:44104
[Errno 111] Connection refused
Connecting to [::ffff:172.17.0.1]:44100
Connecting to [::ffff:172.17.0.1]:44101
Connecting to [::ffff:172.17.0.1]:44102
Connecting to [::ffff:172.17.0.1]:44103
Connecting to [::ffff:172.17.0.1]:44104
Error reading from socket (peer: ('::ffff:172.17.0.1', 44103, 0, 0)): timed out
No data from ::ffff:172.17.0.1:44103. Wait 100ms
Error reading from socket (peer: ('::ffff:172.17.0.1', 44102, 0, 0)): timed out
No data from ::ffff:172.17.0.1:44102. Wait 100ms
